Workbook

Sheet 현물가1.5
A1: RPS 태양광 경제성 분석 (현물시장) | Y1: <=입력 | Z1: 진코 | AB1: 한화, 진코 들 중 하나만 입력
A3: 구분 | B3: 연간 발전량 (kW) | C3: 한국전력 매전금액수익 (SMP) | D3: 공급인증서 수익 (REC) | E3: 총수익 (SMP+REC) | F3: 유지보수비용 (年매출의 3%) | G3: 총수익(SMP+REC) - 유지보수비용 | H3: 평균예상수익(月) (=총수익/12개월) | I3: 누적수익(年) (=수익-유지보수) | J3: 평균 상환액(年) (=대출액+이자) | K3: 평균수익(年) (=수익-대출액-이자) | L3: 누적수익(年) (=수익-대출액-이자) | M3: 상환기간 | N3: 상환일자 | O3: 원금상환액 | P3: 이자상환액 | Q3: 연이자(기간동안) | R3: 월상환액 | S3: 원상환액 (기간동안) | T3: 대출원금잔액 | U3: 상환액+연이자 | V3: 태양광발전사업 세부내용 << 양면모듈 >>
A4: 1년 | B4: =(W5*365*W4) -> 221920 | C4: =B4*$W$6 -> 26852320 | D4: =B4*$W$8*$W$7 -> 23967360 | E4: =C4+D4 -> 50819680 | F4: =(C4+D4)*0.03 -> 1524590.4 | G4: =C4+D4-F4 -> 49295090 | H4: =G4/12 -> 4107924.1 | I4: =G4 -> 49295090 | J4: =SUM(U4:U15) -> 8892000 | K4: =G4-J4 -> 40403090 | L4: =G4-SUM(U4:U15) -> 40403090 | M4: 1 | N4: =EDATE($Z$13,M4) -> 44228 | O4: =IF(M4<=$W$17,0,(IF(M4<=$Z$12,R4-P4,0))) -> 0 | P4: =$W$14*$W$15/12 -> 741000 | Q4: =IF(T4>0,P4,IF(S4>0,P4,0)) -> 741000 | R4: =IF(M4>SUM($W$16:$W$17),0,SUM(O4,Q4)) -> 741000 | S4: =IF(M4<=$W$17,0,(IF(M4<=$Z$12,$Z$14,0))) -> 0 | T4: =$W$14 -> 197600000 | U4: =O4+Q4 -> 741000 | V4: 발전설비용량 (kW) | W4: =Z4 -> 152 | Y4: 설비용량 | Z4: 152
A5: 2년 | B5: =B4*0.99 -> 219700.8 | C5: =B5*$W$6 -> 26583797 | D5: =B5*$W$8*$W$7 -> 23727686 | E5: =C5+D5 -> 50311483 | F5: =(C5+D5)*0.03 -> 1509344.5 | G5: =C5+D5-F5 -> 48802139 | H5: =G5/12 -> 4066844.9 | I5: =SUM(G4:G5) -> 98097228 | J5: =SUM(U16:U27) -> 24574739 | K5: =G5-J5 -> 24227399 | L5: =SUM($G$4:G5)-SUM($U$4:U27) -> 64630489 | M5: 2 | N5: =EDATE($Z$13,M5) -> 44256 | O5: =IF(M5<=$W$17,0,(IF(M5<=$Z$12,R5-P5,0))) -> 0 | P5: =$W$14*$W$15/12 -> 741000 | Q5: =IF(T5>0,P5,IF(S5>0,P5,0)) -> 741000 | R5: =IF(M5>SUM($W$16:$W$17),0,SUM(O5,Q5)) -> 741000 | S5: =IF(M5>$Z$12,0,(IF(M5<=$W$17,0,$Z$14))) -> 0 | T5: =T4-O5 -> 197600000 | U5: =O5+Q5 -> 741000 | V5: 발전시간 (일간 평균) | W5: =Z5 -> 4 | Y5: 발전시간 | Z5: 4 | AB5: 100kW ↓ | AC5: 100~500 | AD5: 500~1000 | AE5: 통합
A6: 3년 | B6: =B5*0.996 -> 218822 | C6: =B6*$W$6 -> 26477462 | D6: =B6*$W$8*$W$7 -> 23632776 | E6: =C6+D6 -> 50110237 | F6: =(C6+D6)*0.03 -> 1503307.1 | G6: =C6+D6-F6 -> 48606930 | H6: =G6/12 -> 4050577.5 | I6: =I5+G6 -> 1.4670416e+08 | J6: =SUM(U28:U39) -> 24574739 | K6: =G6-J6 -> 24032191 | L6: =SUM($G$4:G6)-SUM($U$4:U39) -> 88662679 | M6: 3 | N6: =EDATE($Z$13,M6) -> 44287 | O6: =IF(M6<=$W$17,0,(IF(M6<=$Z$12,S6-P6,0))) -> 0 | P6: =T5*$W$15/12 -> 741000 | Q6: =IF(T6>0,P6,IF(S6>0,P6,0)) -> 741000 | R6: =IF(M6>SUM($W$16:$W$17),0,SUM(O6,Q6)) -> 741000 | S6: =IF(M6>$Z$12,0,(IF(M6<=$W$17,0,$Z$14))) -> 0 | T6: =T5-O6 -> 197600000 | U6: =O6+Q6 -> 741000 | V6: 한전전력매전금액 (SMP) | W6: =SUM(Z6) -> 121 | Y6: SMP | Z6: 121 | AB6: 154.411 | AC6: 139.412 | AD6: 141.464 | AE6: 139.742
A7: 4년 | B7: =B6*0.996 -> 217946.71 | C7: =B7*$W$6 -> 26371552 | D7: =B7*$W$8*$W$7 -> 23538245 | E7: =C7+D7 -> 49909796 | F7: =(C7+D7)*0.03 -> 1497293.9 | G7: =C7+D7-F7 -> 48412502 | H7: =G7/12 -> 4034375.2 | I7: =I6+G7 -> 1.9511666e+08 | J7: =SUM(U40:U51) -> 24574739 | K7: =G7-J7 -> 23837763 | L7: =SUM($G$4:G7)-SUM($U$4:U51) -> 1.1250044e+08 | M7: 4 | N7: =EDATE($Z$13,M7) -> 44317 | O7: =IF(M7<=$W$17,0,(IF(M7<=$Z$12,S7-P7,0))) -> 0 | P7: =T6*$W$15/12 -> 741000 | Q7: =IF(T7>0,P7,IF(S7>0,P7,0)) -> 741000 | R7: =IF(M7>SUM($W$16:$W$17),0,SUM(O7,Q7)) -> 741000 | S7: =IF(M7>$Z$12,0,(IF(M7<=$W$17,0,$Z$14))) -> 0 | T7: =T6-O7 -> 197600000 | U7: =O7+Q7 -> 741000 | V7: 공급인증서 (REC) | W7: 72 | Y7: REC | Z7: 72 | AB7: 81.91 | AC7: 81.91 | AD7: 81.91 | AE7: 81.91
A8: 5년 | B8: =B7*0.996 -> 217074.92 | C8: =B8*$W$6 -> 26266066 | D8: =B8*$W$8*$W$7 -> 23444092 | E8: =C8+D8 -> 49710157 | F8: =(C8+D8)*0.03 -> 1491304.7 | G8: =C8+D8-F8 -> 48218852 | H8: =G8/12 -> 4018237.7 | I8: =I7+G8 -> 2.4333551e+08 | J8: =SUM(U52:U63) -> 24574739 | K8: =G8-J8 -> 23644113 | L8: =SUM($G$4:G8)-SUM($U$4:U63) -> 1.3614456e+08 | M8: 5 | N8: =EDATE($Z$13,M8) -> 44348 | O8: =IF(M8<=$W$17,0,(IF(M8<=$Z$12,S8-P8,0))) -> 0 | P8: =T7*$W$15/12 -> 741000 | Q8: =IF(T8>0,P8,IF(S8>0,P8,0)) -> 741000 | R8: =IF(M8>SUM($W$16:$W$17),0,SUM(O8,Q8)) -> 741000 | S8: =IF(M8>$Z$12,0,(IF(M8<=$W$17,0,$Z$14))) -> 0 | T8: =T7-O8 -> 197600000 | U8: =O8+Q8 -> 741000 | V8: 가중치 | W8: =Z8 -> 1.5 | Y8: 가중치 | Z8: 1.5 | AB8: =AB6-AB7 -> 72.501 | AC8: =AC6-AC7 -> 57.502 | AD8: =AD6-AD7 -> 59.554 | AE8: =AE6-AE7 -> 57.832
A9: 6년 | B9: =B8*0.996 -> 216206.62 | C9: =B9*$W$6 -> 26161001 | D9: =B9*$W$8*$W$7 -> 23350315 | E9: =C9+D9 -> 49511317 | F9: =(C9+D9)*0.03 -> 1485339.5 | G9: =C9+D9-F9 -> 48025977 | H9: =G9/12 -> 4002164.8 | I9: =I8+G9 -> 2.9136149e+08 | J9: =SUM(U64:U75) -> 24574739 | K9: =G9-J9 -> 23451238 | L9: =SUM($G$4:G9)-SUM($U$4:U75) -> 1.5959579e+08 | M9: 6 | N9: =EDATE($Z$13,M9) -> 44378 | O9: =IF(M9<=$W$17,0,(IF(M9<=$Z$12,S9-P9,0))) -> 0 | P9: =T8*$W$15/12 -> 741000 | Q9: =IF(T9>0,P9,IF(S9>0,P9,0)) -> 741000 | R9: =IF(M9>SUM($W$16:$W$17),0,SUM(O9,Q9)) -> 741000 | S9: =IF(M9>$Z$12,0,(IF(M9<=$W$17,0,$Z$14))) -> 0 | T9: =T8-O9 -> 197600000 | U9: =O9+Q9 -> 741000 | V9: ♦ 태양광 설치비용 ♦ | Y9: kw단가 | Z9: 1300000
A10: 7년 | B10: =B9*0.996 -> 215341.8 | C10: =B10*$W$6 -> 26056357 | D10: =B10*$W$8*$W$7 -> 23256914 | E10: =C10+D10 -> 49313271 | F10: =(C10+D10)*0.03 -> 1479398.1 | G10: =C10+D10-F10 -> 47833873 | H10: =G10/12 -> 3986156.1 | I10: =I9+G10 -> 3.3919536e+08 | J10: =SUM(U76:U87) -> 24574739 | K10: =G10-J10 -> 23259134 | L10: =SUM($G$4:G10)-SUM($U$3:U86) -> 1.8490282e+08 | M10: 7 | N10: =EDATE($Z$13,M10) -> 44409 | O10: =IF(M10<=$W$17,0,(IF(M10<=$Z$12,S10-P10,0))) -> 0 | P10: =T9*$W$15/12 -> 741000 | Q10: =IF(T10>0,P10,IF(S10>0,P10,0)) -> 741000 | R10: =IF(M10>SUM($W$16:$W$17),0,SUM(O10,Q10)) -> 741000 | S10: =IF(M10>$Z$12,0,(IF(M10<=$W$17,0,$Z$14))) -> 0 | T10: =T9-O10 -> 197600000 | U10: =O10+Q10 -> 741000 | V10: 공사금액 | W10: =SUM(Z9*Z4) -> 197600000 | Y10: 기타추가비용 (ex.한전선로비) | AB10: 한화 | AC10: 1050000 | AD10: 삭제금지
A11: 8년 | B11: =B10*0.996 -> 214480.43 | C11: =B11*$W$6 -> 25952132 | D11: =B11*$W$8*$W$7 -> 23163886 | E11: =C11+D11 -> 49116018 | F11: =(C11+D11)*0.03 -> 1473480.5 | G11: =C11+D11-F11 -> 47642538 | H11: =G11/12 -> 3970211.5 | I11: =I10+G11 -> 3.868379e+08 | J11: =SUM(U88:U99) -> 24574739 | K11: =G11-J11 -> 23067798 | L11: =SUM($G$4:G11)-SUM($U$4:U99) -> 2.0592272e+08 | M11: 8 | N11: =EDATE($Z$13,M11) -> 44440 | O11: =IF(M11<=$W$17,0,(IF(M11<=$Z$12,S11-P11,0))) -> 0 | P11: =T10*$W$15/12 -> 741000 | Q11: =IF(T11>0,P11,IF(S11>0,P11,0)) -> 741000 | R11: =IF(M11>SUM($W$16:$W$17),0,SUM(O11,Q11)) -> 741000 | S11: =IF(M11>$Z$12,0,(IF(M11<=$W$17,0,$Z$14))) -> 0 | T11: =T10-O11 -> 197600000 | U11: =O11+Q11 -> 741000 | V11: 부가세 | W11: =SUM(W10*0.1) -> 19760000 | Y11: 연이자 | Z11: =W14/365*W15*30*12 -> 8770191.8 | AB11: 진코 | AC11: 950000
A12: 9년 | B12: =B11*0.996 -> 213622.51 | C12: =B12*$W$6 -> 25848323 | D12: =B12*$W$8*$W$7 -> 23071231 | E12: =C12+D12 -> 48919554 | F12: =(C12+D12)*0.03 -> 1467586.6 | G12: =C12+D12-F12 -> 47451967 | H12: =G12/12 -> 3954330.6 | I12: =I11+G12 -> 4.3428987e+08 | J12: =SUM(U100:U111) -> 24574739 | K12: =G12-J12 -> 22877228 | L12: =SUM($G$4:G12)-SUM($U$4:U111) -> 2.2879995e+08 | M12: 9 | N12: =EDATE($Z$13,M12) -> 44470 | O12: =IF(M12<=$W$17,0,(IF(M12<=$Z$12,S12-P12,0))) -> 0 | P12: =T11*$W$15/12 -> 741000 | Q12: =IF(T12>0,P12,IF(S12>0,P12,0)) -> 741000 | R12: =IF(M12>SUM($W$16:$W$17),0,SUM(O12,Q12)) -> 741000 | S12: =IF(M12>$Z$12,0,(IF(M12<=$W$17,0,$Z$14))) -> 0 | T12: =T11-O12 -> 197600000 | U12: =O12+Q12 -> 741000 | V12: ◆총 사업비◆ | W12: =W10+W11 -> 217360000 | Y12: 상환+거치 | Z12: =W17+W16 -> 132
A13: 10년 | B13: =B12*0.996 -> 212768.02 | C13: =B13*$W$6 -> 25744930 | D13: =B13*$W$8*$W$7 -> 22978946 | E13: =C13+D13 -> 48723876 | F13: =(C13+D13)*0.03 -> 1461716.3 | G13: =C13+D13-F13 -> 47262160 | H13: =G13/12 -> 3938513.3 | I13: =I12+G13 -> 4.8155203e+08 | J13: =SUM(U112:U123) -> 24574739 | K13: =G13-J13 -> 22687420 | L13: =SUM($G$4:G13)-SUM($U$4:U123) -> 2.5148737e+08 | M13: 10 | N13: =EDATE($Z$13,M13) -> 44501 | O13: =IF(M13<=$W$17,0,(IF(M13<=$Z$12,S13-P13,0))) -> 0 | P13: =T12*$W$15/12 -> 741000 | Q13: =IF(T13>0,P13,IF(S13>0,P13,0)) -> 741000 | R13: =IF(M13>SUM($W$16:$W$17),0,SUM(O13,Q13)) -> 741000 | S13: =IF(M13>$Z$12,0,(IF(M13<=$W$17,0,$Z$14))) -> 0 | T13: =T12-O13 -> 197600000 | U13: =O13+Q13 -> 741000 | V13: ♦ 태양광 대출비용 ♦ | Y13: 대출일자 | Z13: 44197 | AB13: 진코 | AC13: 950000
A14: 11년 | B14: =B13*0.996 -> 211916.94 | C14: =B14*$W$6 -> 25641950 | D14: =B14*$W$8*$W$7 -> 22887030 | E14: =C14+D14 -> 48528980 | F14: =(C14+D14)*0.03 -> 1455869.4 | G14: =C14+D14-F14 -> 47073111 | H14: =G14/12 -> 3922759.2 | I14: =I13+G14 -> 5.2862514e+08 | J14: =SUM(U124:U135) -> 24574739 | K14: =G14-J14 -> 22498371 | L14: =SUM($G$4:G14)-SUM($U$4:U135) -> 2.7398574e+08 | M14: 11 | N14: =EDATE($Z$13,M14) -> 44531 | O14: =IF(M14<=$W$17,0,(IF(M14<=$Z$12,S14-P14,0))) -> 0 | P14: =T13*$W$15/12 -> 741000 | Q14: =IF(T14>0,P14,IF(S14>0,P14,0)) -> 741000 | R14: =IF(M14>SUM($W$16:$W$17),0,SUM(O14,Q14)) -> 741000 | S14: =IF(M14>$Z$12,0,(IF(M14<=$W$17,0,$Z$14))) -> 0 | T14: =T13-O14 -> 197600000 | U14: =O14+Q14 -> 741000 | V14: 대출액 | W14: =SUM(Z16*Z4) -> 197600000 | Y14: 월상환액 | Z14: =PMT($W$15/12,W16,-W14) -> 2047895
A15: 12년 | B15: =B14*0.996 -> 211069.28 | C15: =B15*$W$6 -> 25539383 | D15: =B15*$W$8*$W$7 -> 22795482 | E15: =C15+D15 -> 48334864 | F15: =(C15+D15)*0.03 -> 1450045.9 | G15: =C15+D15-F15 -> 46884819 | H15: =G15/12 -> 3907068.2 | I15: =I14+G15 -> 5.7550996e+08 | J15: - | K15: =G15 -> 46884819 | L15: =SUM($G$4:G15)-SUM($U$4:U147) -> 3.2087056e+08 | M15: 12 | N15: =EDATE($Z$13,M15) -> 44562 | O15: =IF(M15<=$W$17,0,(IF(M15<=$Z$12,S15-P15,0))) -> 0 | P15: =T14*$W$15/12 -> 741000 | Q15: =IF(T15>0,P15,IF(S15>0,P15,0)) -> 741000 | R15: =IF(M15>SUM($W$16:$W$17),0,SUM(O15,Q15)) -> 741000 | S15: =IF(M15>$Z$12,0,(IF(M15<=$W$17,0,$Z$14))) -> 0 | T15: =T14-O15 -> 197600000 | U15: =O15+Q15 -> 741000 | V15: 년이율 (%) | W15: 0.045
A16: 13년 | B16: =B15*0.996 -> 210225 | C16: =B16*$W$6 -> 25437225 | D16: =B16*$W$8*$W$7 -> 22704300 | E16: =C16+D16 -> 48141525 | F16: =(C16+D16)*0.03 -> 1444245.7 | G16: =C16+D16-F16 -> 46697279 | H16: =G16/12 -> 3891439.9 | I16: =I15+G16 -> 6.2220724e+08 | J16: - | K16: =G16 -> 46697279 | L16: =SUM($G$4:G16)-SUM($U$4:U159) -> 3.6756784e+08 | M16: 13 | N16: =EDATE($Z$13,M16) -> 44593 | O16: =IF(M16<=$W$17,0,(IF(M16<=$Z$12,S16-P16,0))) -> 1306895 | P16: =T15*$W$15/12 -> 741000 | Q16: =IF(T16>0,P16,IF(S16>0,P16,0)) -> 741000 | R16: =IF(M16>SUM($W$16:$W$17),0,SUM(O16,Q16)) -> 2047895 | S16: =IF(M16>$Z$12,0,(IF(M16<=$W$17,0,$Z$14))) -> 2047895 | T16: =T15-O16 -> 1.9629311e+08 | U16: =O16+Q16 -> 2047895 | V16: 상환기간 | W16: 120 | Y16: 대출액 | Z16: 1300000
A17: 14년 | B17: =B16*0.996 -> 209384.1 | C17: =B17*$W$6 -> 25335476 | D17: =B17*$W$8*$W$7 -> 22613483 | E17: =C17+D17 -> 47948959 | F17: =(C17+D17)*0.03 -> 1438468.8 | G17: =C17+D17-F17 -> 46510490 | H17: =G17/12 -> 3875874.2 | I17: =I16+G17 -> 6.6871773e+08 | J17: - | K17: =G17 -> 46510490 | L17: =SUM($G$4:G17)-SUM($U$4:U171) -> 4.1407833e+08 | M17: 14 | N17: =EDATE($Z$13,M17) -> 44621 | O17: =IF(M17<=$W$17,0,(IF(M17<=$Z$12,S17-P17,0))) -> 1311795.8 | P17: =T16*$W$15/12 -> 736099.14 | Q17: =IF(T17>0,P17,IF(S17>0,P17,0)) -> 736099.14 | R17: =IF(M17>SUM($W$16:$W$17),0,SUM(O17,Q17)) -> 2047895 | S17: =IF(M17>$Z$12,0,(IF(M17<=$W$17,0,$Z$14))) -> 2047895 | T17: =T16-O17 -> 1.9498131e+08 | U17: =O17+Q17 -> 2047895 | V17: 거치기간 | W17: 12
A18: 15년 | B18: =B17*0.996 -> 208546.56 | C18: =B18*$W$6 -> 25234134 | D18: =B18*$W$8*$W$7 -> 22523029 | E18: =C18+D18 -> 47757163 | F18: =(C18+D18)*0.03 -> 1432714.9 | G18: =C18+D18-F18 -> 46324448 | H18: =G18/12 -> 3860370.7 | I18: =I17+G18 -> 7.1504218e+08 | J18: - | K18: =G18 -> 46324448 | L18: =SUM($G$4:G18)-SUM($U$4:U183) -> 4.6040278e+08 | M18: 15 | N18: =EDATE($Z$13,M18) -> 44652 | O18: =IF(M18<=$W$17,0,(IF(M18<=$Z$12,S18-P18,0))) -> 1316715 | P18: =T17*$W$15/12 -> 731179.91 | Q18: =IF(T18>0,P18,IF(S18>0,P18,0)) -> 731179.91 | R18: =IF(M18>SUM($W$16:$W$17),0,SUM(O18,Q18)) -> 2047895 | S18: =IF(M18>$Z$12,0,(IF(M18<=$W$17,0,$Z$14))) -> 2047895 | T18: =T17-O18 -> 1.9366459e+08 | U18: =O18+Q18 -> 2047895 | V18: ♦ 태양광 최종수익 ♦
A19: 16년 | B19: =B18*0.996 -> 207712.38 | C19: =B19*$W$6 -> 25133198 | D19: =B19*$W$8*$W$7 -> 22432937 | E19: =C19+D19 -> 47566134 | F19: =(C19+D19)*0.03 -> 1426984 | G19: =C19+D19-F19 -> 46139150 | H19: =G19/12 -> 3844929.2 | I19: =I18+G19 -> 7.6118133e+08 | J19: - | K19: =G19 -> 46139150 | L19: =SUM($G$4:G19)-SUM($U$4:U195) -> 5.0654193e+08 | M19: 16 | N19: =EDATE($Z$13,M19) -> 44682 | O19: =IF(M19<=$W$17,0,(IF(M19<=$Z$12,S19-P19,0))) -> 1321652.7 | P19: =T18*$W$15/12 -> 726242.23 | Q19: =IF(T19>0,P19,IF(S19>0,P19,0)) -> 726242.23 | R19: =IF(M19>SUM($W$16:$W$17),0,SUM(O19,Q19)) -> 2047895 | S19: =IF(M19>$Z$12,0,(IF(M19<=$W$17,0,$Z$14))) -> 2047895 | T19: =T18-O19 -> 1.9234294e+08 | U19: =O19+Q19 -> 2047895 | V19: ROI (투자자본수익률) | W19: =I4/W12 -> 0.22679007
A20: 17년 | B20: =B19*0.996 -> 206881.53 | C20: =B20*$W$6 -> 25032665 | D20: =B20*$W$8*$W$7 -> 22343205 | E20: =C20+D20 -> 47375870 | F20: =(C20+D20)*0.03 -> 1421276.1 | G20: =C20+D20-F20 -> 45954594 | H20: =G20/12 -> 3829549.5 | I20: =I19+G20 -> 8.0713592e+08 | J20: - | K20: =G20 -> 45954594 | L20: =SUM($G$4:G20)-SUM($U$4:U207) -> 5.5249652e+08 | M20: 17 | N20: =EDATE($Z$13,M20) -> 44713 | O20: =IF(M20<=$W$17,0,(IF(M20<=$Z$12,S20-P20,0))) -> 1326608.9 | P20: =T19*$W$15/12 -> 721286.03 | Q20: =IF(T20>0,P20,IF(S20>0,P20,0)) -> 721286.03 | R20: =IF(M20>SUM($W$16:$W$17),0,SUM(O20,Q20)) -> 2047895 | S20: =IF(M20>$Z$12,0,(IF(M20<=$W$17,0,$Z$14))) -> 2047895 | T20: =T19-O20 -> 1.9101633e+08 | U20: =O20+Q20 -> 2047895 | V20: 손익분기점 (년) | W20: =W12/I4 -> 4.4093641
A21: 18년 | B21: =B20*0.996 -> 206054 | C21: =B21*$W$6 -> 24932534 | D21: =B21*$W$8*$W$7 -> 22253832 | E21: =C21+D21 -> 47186366 | F21: =(C21+D21)*0.03 -> 1415591 | G21: =C21+D21-F21 -> 45770775 | H21: =G21/12 -> 3814231.3 | I21: =I20+G21 -> 8.5290669e+08 | J21: - | K21: =G21 -> 45770775 | L21: =SUM($G$4:G21)-SUM($U$4:U219) -> 5.982673e+08 | M21: 18 | N21: =EDATE($Z$13,M21) -> 44743 | O21: =IF(M21<=$W$17,0,(IF(M21<=$Z$12,S21-P21,0))) -> 1331583.7 | P21: =T20*$W$15/12 -> 716311.25 | Q21: =IF(T21>0,P21,IF(S21>0,P21,0)) -> 716311.25 | R21: =IF(M21>SUM($W$16:$W$17),0,SUM(O21,Q21)) -> 2047895 | S21: =IF(M21>$Z$12,0,(IF(M21<=$W$17,0,$Z$14))) -> 2047895 | T21: =T20-O21 -> 1.8968475e+08 | U21: =O21+Q21 -> 2047895 | V21: 20년 총수익 (無대출) | W21: =I23 -> 9.4389973e+08
A22: 19년 | B22: =B21*0.996 -> 205229.79 | C22: =B22*$W$6 -> 24832804 | D22: =B22*$W$8*$W$7 -> 22164817 | E22: =C22+D22 -> 46997621 | F22: =(C22+D22)*0.03 -> 1409928.6 | G22: =C22+D22-F22 -> 45587692 | H22: =G22/12 -> 3798974.4 | I22: =I21+G22 -> 8.9849439e+08 | J22: - | K22: =G22 -> 45587692 | L22: =SUM($G$4:G22)-SUM($U$4:U231) -> 6.4385499e+08 | M22: 19 | N22: =EDATE($Z$13,M22) -> 44774 | O22: =IF(M22<=$W$17,0,(IF(M22<=$Z$12,S22-P22,0))) -> 1336577.1 | P22: =T21*$W$15/12 -> 711317.81 | Q22: =IF(T22>0,P22,IF(S22>0,P22,0)) -> 711317.81 | R22: =IF(M22>SUM($W$16:$W$17),0,SUM(O22,Q22)) -> 2047895 | S22: =IF(M22>$Z$12,0,(IF(M22<=$W$17,0,$Z$14))) -> 2047895 | T22: =T21-O22 -> 1.8834817e+08 | U22: =O22+Q22 -> 2047895 | V22: 20년 총수익 (대출적용) | W22: =L23 -> 6.8926033e+08
A23: 20년 | B23: =B22*0.996 -> 204408.87 | C23: =B23*$W$6 -> 24733473 | D23: =B23*$W$8*$W$7 -> 22076158 | E23: =C23+D23 -> 46809630 | F23: =(C23+D23)*0.03 -> 1404288.9 | G23: =C23+D23-F23 -> 45405342 | H23: =G23/12 -> 3783778.5 | I23: =I22+G23 -> 9.4389973e+08 | J23: - | K23: =G23 -> 45405342 | L23: =SUM($G$4:G23)-SUM($U$4:U243) -> 6.8926033e+08 | M23: 20 | N23: =EDATE($Z$13,M23) -> 44805 | O23: =IF(M23<=$W$17,0,(IF(M23<=$Z$12,S23-P23,0))) -> 1341589.3 | P23: =T22*$W$15/12 -> 706305.64 | Q23: =IF(T23>0,P23,IF(S23>0,P23,0)) -> 706305.64 | R23: =IF(M23>SUM($W$16:$W$17),0,SUM(O23,Q23)) -> 2047895 | S23: =IF(M23>$Z$12,0,(IF(M23<=$W$17,0,$Z$14))) -> 2047895 | T23: =T22-O23 -> 1.8700658e+08 | U23: =O23+Q23 -> 2047895
A24: # 이 수지분석은 2024년 현물시장 기준 수익분석 자료입니다. # 선로 개통비 , 구조 보강비 별도 / 순 공사비 기준 수익분석 자료 입니다. | M24: 21 | N24: =EDATE($Z$13,M24) -> 44835 | O24: =IF(M24<=$W$17,0,(IF(M24<=$Z$12,S24-P24,0))) -> 1346620.3 | P24: =T23*$W$15/12 -> 701274.68 | Q24: =IF(T24>0,P24,IF(S24>0,P24,0)) -> 701274.68 | R24: =IF(M24>SUM($W$16:$W$17),0,SUM(O24,Q24)) -> 2047895 | S24: =IF(M24>$Z$12,0,(IF(M24<=$W$17,0,$Z$14))) -> 2047895 | T24: =T23-O24 -> 1.8565996e+08 | U24: =O24+Q24 -> 2047895
M25: 22 | N25: =EDATE($Z$13,M25) -> 44866 | O25: =IF(M25<=$W$17,0,(IF(M25<=$Z$12,S25-P25,0))) -> 1351670.1 | P25: =T24*$W$15/12 -> 696224.86 | Q25: =IF(T25>0,P25,IF(S25>0,P25,0)) -> 696224.86 | R25: =IF(M25>SUM($W$16:$W$17),0,SUM(O25,Q25)) -> 2047895 | S25: =IF(M25>$Z$12,0,(IF(M25<=$W$17,0,$Z$14))) -> 2047895 | T25: =T24-O25 -> 1.8430829e+08 | U25: =O25+Q25 -> 2047895
M26: 23 | N26: =EDATE($Z$13,M26) -> 44896 | O26: =IF(M26<=$W$17,0,(IF(M26<=$Z$12,S26-P26,0))) -> 1356738.9 | P26: =T25*$W$15/12 -> 691156.09 | Q26: =IF(T26>0,P26,IF(S26>0,P26,0)) -> 691156.09 | R26: =IF(M26>SUM($W$16:$W$17),0,SUM(O26,Q26)) -> 2047895 | S26: =IF(M26>$Z$12,0,(IF(M26<=$W$17,0,$Z$14))) -> 2047895 | T26: =T25-O26 -> 1.8295155e+08 | U26: =O26+Q26 -> 2047895
M27: 24 | N27: =EDATE($Z$13,M27) -> 44927 | O27: =IF(M27<=$W$17,0,(IF(M27<=$Z$12,S27-P27,0))) -> 1361826.6 | P27: =T26*$W$15/12 -> 686068.32 | Q27: =IF(T27>0,P27,IF(S27>0,P27,0)) -> 686068.32 | R27: =IF(M27>SUM($W$16:$W$17),0,SUM(O27,Q27)) -> 2047895 | S27: =IF(M27>$Z$12,0,(IF(M27<=$W$17,0,$Z$14))) -> 2047895 | T27: =T26-O27 -> 1.8158973e+08 | U27: =O27+Q27 -> 2047895
M28: 25 | N28: =EDATE($Z$13,M28) -> 44958 | O28: =IF(M28<=$W$17,0,(IF(M28<=$Z$12,S28-P28,0))) -> 1366933.5 | P28: =T27*$W$15/12 -> 680961.47 | Q28: =IF(T28>0,P28,IF(S28>0,P28,0)) -> 680961.47 | R28: =IF(M28>SUM($W$16:$W$17),0,SUM(O28,Q28)) -> 2047895 | S28: =IF(M28>$Z$12,0,(IF(M28<=$W$17,0,$Z$14))) -> 2047895 | T28: =T27-O28 -> 1.8022279e+08 | U28: =O28+Q28 -> 2047895
M29: 26 | N29: =EDATE($Z$13,M29) -> 44986 | O29: =IF(M29<=$W$17,0,(IF(M29<=$Z$12,S29-P29,0))) -> 1372059.5 | P29: =T28*$W$15/12 -> 675835.47 | Q29: =IF(T29>0,P29,IF(S29>0,P29,0)) -> 675835.47 | R29: =IF(M29>SUM($W$16:$W$17),0,SUM(O29,Q29)) -> 2047895 | S29: =IF(M29>$Z$12,0,(IF(M29<=$W$17,0,$Z$14))) -> 2047895 | T29: =T28-O29 -> 1.7885073e+08 | U29: =O29+Q29 -> 2047895
M30: 27 | N30: =EDATE($Z$13,M30) -> 45017 | O30: =IF(M30<=$W$17,0,(IF(M30<=$Z$12,S30-P30,0))) -> 1377204.7 | P30: =T29*$W$15/12 -> 670690.25 | Q30: =IF(T30>0,P30,IF(S30>0,P30,0)) -> 670690.25 | R30: =IF(M30>SUM($W$16:$W$17),0,SUM(O30,Q30)) -> 2047895 | S30: =IF(M30>$Z$12,0,(IF(M30<=$W$17,0,$Z$14))) -> 2047895 | T30: =T29-O30 -> 1.7747353e+08 | U30: =O30+Q30 -> 2047895
M31: 28 | N31: =EDATE($Z$13,M31) -> 45047 | O31: =IF(M31<=$W$17,0,(IF(M31<=$Z$12,S31-P31,0))) -> 1382369.2 | P31: =T30*$W$15/12 -> 665525.73 | Q31: =IF(T31>0,P31,IF(S31>0,P31,0)) -> 665525.73 | R31: =IF(M31>SUM($W$16:$W$17),0,SUM(O31,Q31)) -> 2047895 | S31: =IF(M31>$Z$12,0,(IF(M31<=$W$17,0,$Z$14))) -> 2047895 | T31: =T30-O31 -> 1.7609116e+08 | U31: =O31+Q31 -> 2047895
M32: 29 | N32: =EDATE($Z$13,M32) -> 45078 | O32: =IF(M32<=$W$17,0,(IF(M32<=$Z$12,S32-P32,0))) -> 1387553.1 | P32: =T31*$W$15/12 -> 660341.85 | Q32: =IF(T32>0,P32,IF(S32>0,P32,0)) -> 660341.85 | R32: =IF(M32>SUM($W$16:$W$17),0,SUM(O32,Q32)) -> 2047895 | S32: =IF(M32>$Z$12,0,(IF(M32<=$W$17,0,$Z$14))) -> 2047895 | T32: =T31-O32 -> 1.7470361e+08 | U32: =O32+Q32 -> 2047895
M33: 30 | N33: =EDATE($Z$13,M33) -> 45108 | O33: =IF(M33<=$W$17,0,(IF(M33<=$Z$12,S33-P33,0))) -> 1392756.4 | P33: =T32*$W$15/12 -> 655138.52 | Q33: =IF(T33>0,P33,IF(S33>0,P33,0)) -> 655138.52 | R33: =IF(M33>SUM($W$16:$W$17),0,SUM(O33,Q33)) -> 2047895 | S33: =IF(M33>$Z$12,0,(IF(M33<=$W$17,0,$Z$14))) -> 2047895 | T33: =T32-O33 -> 1.7331085e+08 | U33: =O33+Q33 -> 2047895
M34: 31 | N34: =EDATE($Z$13,M34) -> 45139 | O34: =IF(M34<=$W$17,0,(IF(M34<=$Z$12,S34-P34,0))) -> 1397979.3 | P34: =T33*$W$15/12 -> 649915.69 | Q34: =IF(T34>0,P34,IF(S34>0,P34,0)) -> 649915.69 | R34: =IF(M34>SUM($W$16:$W$17),0,SUM(O34,Q34)) -> 2047895 | S34: =IF(M34>$Z$12,0,(IF(M34<=$W$17,0,$Z$14))) -> 2047895 | T34: =T33-O34 -> 1.7191287e+08 | U34: =O34+Q34 -> 2047895
M35: 32 | N35: =EDATE($Z$13,M35) -> 45170 | O35: =IF(M35<=$W$17,0,(IF(M35<=$Z$12,S35-P35,0))) -> 1403221.7 | P35: =T34*$W$15/12 -> 644673.27 | Q35: =IF(T35>0,P35,IF(S35>0,P35,0)) -> 644673.27 | R35: =IF(M35>SUM($W$16:$W$17),0,SUM(O35,Q35)) -> 2047895 | S35: =IF(M35>$Z$12,0,(IF(M35<=$W$17,0,$Z$14))) -> 2047895 | T35: =T34-O35 -> 1.7050965e+08 | U35: =O35+Q35 -> 2047895
M36: 33 | N36: =EDATE($Z$13,M36) -> 45200 | O36: =IF(M36<=$W$17,0,(IF(M36<=$Z$12,S36-P36,0))) -> 1408483.8 | P36: =T35*$W$15/12 -> 639411.18 | Q36: =IF(T36>0,P36,IF(S36>0,P36,0)) -> 639411.18 | R36: =IF(M36>SUM($W$16:$W$17),0,SUM(O36,Q36)) -> 2047895 | S36: =IF(M36>$Z$12,0,(IF(M36<=$W$17,0,$Z$14))) -> 2047895 | T36: =T35-O36 -> 1.6910117e+08 | U36: =O36+Q36 -> 2047895
... M243: 240 | N243: =EDATE($Z$13,M243) -> 51502 | O243: =IF(M243<=$W$17,0,(IF(M243<=$Z$12,S243-P243,0))) -> 0 | P243: =T242*$W$15/12 -> -3.1082891e-10 | Q243: =IF(T243>0,P243,IF(S243>0,P243,0)) -> 0 | R243: =IF(M243>SUM($W$16:$W$17),0,SUM(O243,Q243)) -> 0 | S243: =IF(M243>$Z$12,0,(IF(M243<=$W$17,0,$Z$14))) -> 0 | T243: =T242-O243 -> -8.2887709e-08 | U243: =O243+Q243 -> 0

Sheet 견적서
A1: 견 적 서
A3: 사업주 | C3: 귀하 | E3: │주│솔 라 엘 디 (인)
A5: 현 장 명 : 경북 영천시 청통면 죽정리 576 | F5: ◈주 소: 대구광역시 동구 메디밸리로19 401호
F6: 전 화 : (0 5 3) 8 5 6 - 9 6 9 8
A7: 공 사 명 : 태양광설치 공사 | F7: F A X : (0 5 3) 2 8 9 - 6 6 9 8
A9: 하기와 같이 견적합니다. | G9: 견적송부일 : | H9: =TODAY() -> 46133
H14: (금액단위:원/VAT별도)
A15: 기호 | B15: 품 명 | C15: 규 격 | D15: 단 위 | E15: 수 량 | F15: 단 가 | G15: 금 액 | H15: 비 고 | J15: 삭제금지
A16: 1 | B16: =K23 -> 진코 620W 무등급 양면모듈 | E16: =$P$16 -> 250 | G16: =Q16 -> 0 | J16: =현물가1.5!$Z$4 -> 152 | K16: 1000 | L16: =PRODUCT(J16:K16) -> 152000 | M16: 600 | N16: =L16/M16 -> 253.33333 | O16: =ROUND(N16,-1) -> 250 | P16: =ROUNDUP(O16,-1) -> 250
A17: 2 | B17: 현대 60KW | E17: =M17 -> 4 | G17: 0 | J17: =현물가1.5!$Z$4 -> 152 | K17: 50 | L17: =J17/K17 -> 3.04 | M17: =ROUNDUP(L17,0) -> 4
B19: 태양광 발전소 공사 | G19: =현물가1.5!W10 -> 197600000
A20: * 견적조건 | J20: 한화 | K20: 한화 600W 무등급 양면모듈
B21: 1. VAT별도 | J21: 진코 | K21: 진코 620W 무등급 양면모듈
B22: 2. 모듈 : 제조사 보증서 제출
B23: 3. 인버터 : 제조사 보증서 제출 | J23: =현물가1.5!Z1 -> 진코 | K23: =IF(J23=J21,K21,K20) -> 진코 620W 무등급 양면모듈
B24: 4. 한전연계비용 별도 (표준시설부담금)
B25: 5. 안전관리자 선임 별도
B26: 6. 보강 발생 시 비용 별도 ( 실비처리 )

Sheet 작업용
A1: ="RPS 태양광 경제성 분석 (현물시장) ["&Y1&"]" -> RPS 태양광 경제성 분석 (현물시장) [진코] | X1: <=입력 | Y1: 진코 | AA1: 한화, 진코 들 중 하나만 입력
A3: 구분 | B3: 연간 발전량 (kW) ((양면+10%)) | C3: 한국전력 매전금액수익 (SMP) | D3: 공급인증서 수익 (REC) | E3: 총수익 (SMP+REC) | F3: 유지보수비용 (年매출의 3%) | G3: 총수익(SMP+REC) - 유지보수비용 | H3: 평균예상수익(月) (=총수익/12개월) | I3: 누적수익(年) (=수익-유지보수) | J3: 평균예상수익(月) (=수익-대출액-이자) | K3: 누적수익(年) (=수익-대출액-이자) | L3: 상환기간 | M3: 상환일자 | N3: 원금상환액 | O3: 이자상환액 | P3: 연이자(기간동안) | Q3: 월상환액 | R3: 원상환액 (기간동안) | S3: 대출원금잔액 | T3: 상환액+연이자 | U3: 태양광발전사업 세부내용 << 양면모듈 >>
A4: 1년 | B4: =(V5*365*V4)*110% -> 803000 | C4: =B4*$V$6 -> 1.1808918e+08 | D4: =B4*$V$8*$V$7 -> 95362674 | E4: =C4+D4 -> 2.1345185e+08 | F4: =(C4+D4)*0.03 -> 6403555.6 | G4: =C4+D4-F4 -> 2.070483e+08 | H4: =G4/12 -> 17254025 | I4: =G4 -> 2.070483e+08 | J4: =H4-(SUM($P$4:$P$15)/12) -> 14847775 | K4: =G4-SUM(P4:P15) -> 1.781733e+08 | L4: 1 | M4: =EDATE($Y$13,L4) -> 44228 | P4: =IF(S4>0,O4,IF(R4>0,O4,0)) -> 0 | R4: =IF(L4<=$V$17,0,(IF(L4<=$Y$12,$Y$14,0))) -> 0 | S4: =$V$14 -> 525000000 | T4: =Q4+P4 -> 0 | U4: 발전설비용량 (kW) | V4: =Y4 -> 500 | X4: 설비용량 | Y4: 500
A5: 2년 | B5: =B4*0.995 -> 798985 | C5: =B5*$V$6 -> 1.1749873e+08 | D5: =B5*$V$8*$V$7 -> 94885861 | E5: =C5+D5 -> 2.1238459e+08 | F5: =(C5+D5)*0.03 -> 6371537.8 | G5: =C5+D5-F5 -> 2.0601306e+08 | H5: =G5/12 -> 17167755 | I5: =SUM(G4:G5) -> 4.1306136e+08 | J5: =H5-(SUM($P$4:$P$15)/12) -> 14761505 | K5: =SUM($G$4:G5)-SUM($P$4:P27) -> 3.5268636e+08 | L5: 2 | M5: =EDATE($Y$13,L5) -> 44256 | N5: =IF(L5<=$V$17,0,(IF(L5<=$Y$12,Q5-O5,0))) -> 0 | O5: =$V$14*$V$15/12 -> 2625000 | P5: =IF(S5>0,O5,IF(R5>0,O5,0)) -> 2625000 | Q5: =IF(L5>SUM($V$16:$V$17),0,SUM(N5,P5)) -> 2625000 | R5: =IF(L5>$Y$12,0,(IF(L5<=$V$17,0,$Y$14))) -> 0 | S5: =S4-N5 -> 525000000 | T5: =N5+P5 -> 2625000 | U5: 발전시간 (일간 평균) | V5: =Y5 -> 4 | X5: 발전시간 | Y5: 4 | AA5: 100kW ↓ | AB5: 100~500 | AC5: 500~1000 | AD5: 통합
A6: 3년 | B6: =B5*0.995 -> 794990.08 | C6: =B6*$V$6 -> 1.1691124e+08 | D6: =B6*$V$8*$V$7 -> 94411431 | E6: =C6+D6 -> 2.1132267e+08 | F6: =(C6+D6)*0.03 -> 6339680.2 | G6: =C6+D6-F6 -> 2.0498299e+08 | H6: =G6/12 -> 17081916 | I6: =I5+G6 -> 6.1804435e+08 | J6: =H6-(SUM($P$4:$P$15)/12) -> 14675666 | K6: =SUM($G$4:G6)-SUM($P$4:P39) -> 5.2616935e+08 | L6: 3 | M6: =EDATE($Y$13,L6) -> 44287 | N6: =IF(L6<=$V$17,0,(IF(L6<=$Y$12,R6-O6,0))) -> 0 | O6: =S5*$V$15/12 -> 2625000 | P6: =IF(S6>0,O6,IF(R6>0,O6,0)) -> 2625000 | Q6: =IF(L6>SUM($V$16:$V$17),0,SUM(N6,P6)) -> 2625000 | R6: =IF(L6>$Y$12,0,(IF(L6<=$V$17,0,$Y$14))) -> 0 | S6: =S5-N6 -> 525000000 | T6: =N6+P6 -> 2625000 | U6: 한전전력매전금액 (SMP) | V6: =Y6 -> 147.06 | X6: SMP | Y6: 147.06 | AA6: 154.411 | AB6: 139.412 | AC6: 141.464 | AD6: 139.742
A7: 4년 | B7: =B6*0.995 -> 791015.12 | C7: =B7*$V$6 -> 1.1632668e+08 | D7: =B7*$V$8*$V$7 -> 93939374 | E7: =C7+D7 -> 2.1026606e+08 | F7: =(C7+D7)*0.03 -> 6307981.8 | G7: =C7+D7-F7 -> 2.0395808e+08 | H7: =G7/12 -> 16996506 | I7: =I6+G7 -> 8.2200242e+08 | J7: =H7-(SUM($P$4:$P$15)/12) -> 14590256 | K7: =SUM($G$4:G7)-SUM($T$4:T51) -> 6.9862742e+08 | L7: 4 | M7: =EDATE($Y$13,L7) -> 44317 | N7: =IF(L7<=$V$17,0,(IF(L7<=$Y$12,R7-O7,0))) -> 0 | O7: =S6*$V$15/12 -> 2625000 | P7: =IF(S7>0,O7,IF(R7>0,O7,0)) -> 2625000 | Q7: =IF(L7>SUM($V$16:$V$17),0,SUM(N7,P7)) -> 2625000 | R7: =IF(L7>$Y$12,0,(IF(L7<=$V$17,0,$Y$14))) -> 0 | S7: =S6-N7 -> 525000000 | T7: =N7+P7 -> 2625000 | U7: 공급인증서 (REC) | V7: =Y7 -> 79.172 | X7: REC | Y7: 79.172 | AA7: 81.91 | AB7: 81.91 | AC7: 81.91 | AD7: 81.91
A8: 5년 | B8: =B7*0.995 -> 787060.05 | C8: =B8*$V$6 -> 1.1574505e+08 | D8: =B8*$V$8*$V$7 -> 93469677 | E8: =C8+D8 -> 2.0921473e+08 | F8: =(C8+D8)*0.03 -> 6276441.8 | G8: =C8+D8-F8 -> 2.0293829e+08 | H8: =G8/12 -> 16911524 | I8: =I7+G8 -> 1.0249407e+09 | J8: =H8-(SUM($P$4:$P$15)/12) -> 14505274 | K8: =SUM($G$4:G8)-SUM($P$4:P63) -> 8.7006571e+08 | L8: 5 | M8: =EDATE($Y$13,L8) -> 44348 | N8: =IF(L8<=$V$17,0,(IF(L8<=$Y$12,R8-O8,0))) -> 0 | O8: =S7*$V$15/12 -> 2625000 | P8: =IF(S8>0,O8,IF(R8>0,O8,0)) -> 2625000 | Q8: =IF(L8>SUM($V$16:$V$17),0,SUM(N8,P8)) -> 2625000 | R8: =IF(L8>$Y$12,0,(IF(L8<=$V$17,0,$Y$14))) -> 0 | S8: =S7-N8 -> 525000000 | T8: =N8+P8 -> 2625000 | U8: 가중치 | V8: =Y8 -> 1.5 | X8: 가중치 | Y8: 1.5 | AA8: =AA6-AA7 -> 72.501 | AB8: =AB6-AB7 -> 57.502 | AC8: =AC6-AC7 -> 59.554 | AD8: =AD6-AD7 -> 57.832
A9: 6년 | B9: =B8*0.995 -> 783124.75 | C9: =B9*$V$6 -> 1.1516633e+08 | D9: =B9*$V$8*$V$7 -> 93002329 | E9: =C9+D9 -> 2.0816865e+08 | F9: =(C9+D9)*0.03 -> 6245059.6 | G9: =C9+D9-F9 -> 2.0192359e+08 | H9: =G9/12 -> 16826966 | I9: =I8+G9 -> 1.2268643e+09 | J9: =H9-(SUM($P$4:$P$15)/12) -> 14420716 | K9: =SUM($G$4:G9)-SUM($T$4:T75) -> 1.0020464e+09 | L9: 6 | M9: =EDATE($Y$13,L9) -> 44378 | N9: =IF(L9<=$V$17,0,(IF(L9<=$Y$12,R9-O9,0))) -> 0 | O9: =S8*$V$15/12 -> 2625000 | P9: =IF(S9>0,O9,IF(R9>0,O9,0)) -> 2625000 | Q9: =IF(L9>SUM($V$16:$V$17),0,SUM(N9,P9)) -> 2625000 | R9: =IF(L9>$Y$12,0,(IF(L9<=$V$17,0,$Y$14))) -> 0 | S9: =S8-N9 -> 525000000 | T9: =N9+P9 -> 2625000 | U9: ♦ 태양광 설치비용 ♦ | X9: kw단가 | Y9: =AB13 -> 1000000
A10: 7년 | B10: =B9*0.995 -> 779209.13 | C10: =B10*$V$6 -> 1.1459049e+08 | D10: =B10*$V$8*$V$7 -> 92537317 | E10: =C10+D10 -> 2.0712781e+08 | F10: =(C10+D10)*0.03 -> 6213834.3 | G10: =C10+D10-F10 -> 2.0091398e+08 | H10: =G10/12 -> 16742831 | I10: =I9+G10 -> 1.4277783e+09 | J10: =H10-(SUM($P$4:$P$15)/12) -> 14336581 | K10: =SUM($G$4:G10)-SUM($P$3:P86) -> 1.2167263e+09 | L10: 7 | M10: =EDATE($Y$13,L10) -> 44409 | N10: =IF(L10<=$V$17,0,(IF(L10<=$Y$12,R10-O10,0))) -> 0 | O10: =S9*$V$15/12 -> 2625000 | P10: =IF(S10>0,O10,IF(R10>0,O10,0)) -> 2625000 | Q10: =IF(L10>SUM($V$16:$V$17),0,SUM(N10,P10)) -> 2625000 | R10: =IF(L10>$Y$12,0,(IF(L10<=$V$17,0,$Y$14))) -> 0 | S10: =S9-N10 -> 525000000 | T10: =N10+P10 -> 2625000 | U10: 공사금액 | V10: =SUM(Y9*Y4) -> 500000000 | X10: 기타추가비용 (ex.한전선로비) | AA10: 한화 | AB10: 1100000 | AC10: 삭제금지
A11: 8년 | B11: =B10*0.995 -> 775313.08 | C11: =B11*$V$6 -> 1.1401754e+08 | D11: =B11*$V$8*$V$7 -> 92074631 | E11: =C11+D11 -> 2.0609217e+08 | F11: =(C11+D11)*0.03 -> 6182765.2 | G11: =C11+D11-F11 -> 1.9990941e+08 | H11: =G11/12 -> 16659117 | I11: =I10+G11 -> 1.6276877e+09 | J11: =H11-(SUM($P$4:$P$15)/12) -> 14252867 | K11: =SUM($G$4:G11)-SUM($P$4:P99) -> 1.3890002e+09 | L11: 8 | M11: =EDATE($Y$13,L11) -> 44440 | N11: =IF(L11<=$V$17,0,(IF(L11<=$Y$12,R11-O11,0))) -> 0 | O11: =S10*$V$15/12 -> 2625000 | P11: =IF(S11>0,O11,IF(R11>0,O11,0)) -> 2625000 | Q11: =IF(L11>SUM($V$16:$V$17),0,SUM(N11,P11)) -> 2625000 | R11: =IF(L11>$Y$12,0,(IF(L11<=$V$17,0,$Y$14))) -> 0 | S11: =S10-N11 -> 525000000 | T11: =N11+P11 -> 2625000 | U11: 부가세 | V11: =SUM(V10*0.1) -> 50000000 | X11: 연이자 | Y11: =V14/365*V15*30*12 -> 31068493 | AA11: 진코 | AB11: 1000000
A12: 9년 | B12: =B11*0.995 -> 771436.51 | C12: =B12*$V$6 -> 1.1344745e+08 | D12: =B12*$V$8*$V$7 -> 91614258 | E12: =C12+D12 -> 2.0506171e+08 | F12: =(C12+D12)*0.03 -> 6151851.3 | G12: =C12+D12-F12 -> 1.9890986e+08 | H12: =G12/12 -> 16575822 | I12: =I11+G12 -> 1.8265975e+09 | J12: =H12-(SUM($P$4:$P$15)/12) -> 14169572 | K12: =SUM($G$4:G12)-SUM($P$4:P111) -> 1.5652574e+09 | L12: 9 | M12: =EDATE($Y$13,L12) -> 44470 | N12: =IF(L12<=$V$17,0,(IF(L12<=$Y$12,R12-O12,0))) -> 0 | O12: =S11*$V$15/12 -> 2625000 | P12: =IF(S12>0,O12,IF(R12>0,O12,0)) -> 2625000 | Q12: =IF(L12>SUM($V$16:$V$17),0,SUM(N12,P12)) -> 2625000 | R12: =IF(L12>$Y$12,0,(IF(L12<=$V$17,0,$Y$14))) -> 0 | S12: =S11-N12 -> 525000000 | T12: =N12+P12 -> 2625000 | U12: ◆총 사업비◆ | V12: =V10+V11 -> 550000000 | X12: 상환+거치 | Y12: =V17+V16 -> 180
A13: 10년 | B13: =B12*0.995 -> 767579.33 | C13: =B13*$V$6 -> 1.1288022e+08 | D13: =B13*$V$8*$V$7 -> 91156186 | E13: =C13+D13 -> 2.040364e+08 | F13: =(C13+D13)*0.03 -> 6121092.1 | G13: =C13+D13-F13 -> 1.9791531e+08 | H13: =G13/12 -> 16492943 | I13: =I12+G13 -> 2.0245129e+09 | J13: =H13-(SUM($P$4:$P$15)/12) -> 14086693 | K13: =SUM($G$4:G13)-SUM($P$4:P123) -> 1.7434369e+09 | L13: 10 | M13: =EDATE($Y$13,L13) -> 44501 | N13: =IF(L13<=$V$17,0,(IF(L13<=$Y$12,R13-O13,0))) -> 0 | O13: =S12*$V$15/12 -> 2625000 | P13: =IF(S13>0,O13,IF(R13>0,O13,0)) -> 2625000 | Q13: =IF(L13>SUM($V$16:$V$17),0,SUM(N13,P13)) -> 2625000 | R13: =IF(L13>$Y$12,0,(IF(L13<=$V$17,0,$Y$14))) -> 0 | S13: =S12-N13 -> 525000000 | T13: =N13+P13 -> 2625000 | U13: ♦ 태양광 대출비용 ♦ | X13: 대출일자 | Y13: 44197 | AA13: 진코 | AB13: =IF(AA13=Y1,AB11,AB10) -> 1000000
A14: 11년 | B14: =B13*0.995 -> 763741.43 | C14: =B14*$V$6 -> 1.1231582e+08 | D14: =B14*$V$8*$V$7 -> 90700405 | E14: =C14+D14 -> 2.0301622e+08 | F14: =(C14+D14)*0.03 -> 6090486.6 | G14: =C14+D14-F14 -> 1.9692573e+08 | H14: =G14/12 -> 16410478 | I14: =I13+G14 -> 2.2214386e+09 | J14: =H14-(SUM($P$4:$P$15)/12) -> 14004228 | K14: =SUM($G$4:G14)-SUM($P$4:P135) -> 1.9237235e+09 | L14: 11 | M14: =EDATE($Y$13,L14) -> 44531 | N14: =IF(L14<=$V$17,0,(IF(L14<=$Y$12,R14-O14,0))) -> 0 | O14: =S13*$V$15/12 -> 2625000 | P14: =IF(S14>0,O14,IF(R14>0,O14,0)) -> 2625000 | Q14: =IF(L14>SUM($V$16:$V$17),0,SUM(N14,P14)) -> 2625000 | R14: =IF(L14>$Y$12,0,(IF(L14<=$V$17,0,$Y$14))) -> 0 | S14: =S13-N14 -> 525000000 | T14: =N14+P14 -> 2625000 | U14: 대출액 | V14: =SUM(Y16*Y4) -> 525000000 | X14: 월상환액 | Y14: =PMT($V$15/12,V16,-V14) -> 5828576.4
A15: 12년 | B15: =B14*0.995 -> 759922.73 | C15: =B15*$V$6 -> 1.1175424e+08 | D15: =B15*$V$8*$V$7 -> 90246903 | E15: =C15+D15 -> 2.0200114e+08 | F15: =(C15+D15)*0.03 -> 6060034.2 | G15: =C15+D15-F15 -> 1.9594111e+08 | H15: =G15/12 -> 16328425 | I15: =I14+G15 -> 2.4173797e+09 | J15: =H15-(SUM($P$4:$P$15)/12) -> 13922175 | K15: =SUM($G$4:G15)-SUM($P$4:P147) -> 2.1063131e+09 | L15: 12 | M15: =EDATE($Y$13,L15) -> 44562 | N15: =IF(L15<=$V$17,0,(IF(L15<=$Y$12,R15-O15,0))) -> 0 | O15: =S14*$V$15/12 -> 2625000 | P15: =IF(S15>0,O15,IF(R15>0,O15,0)) -> 2625000 | Q15: =IF(L15>SUM($V$16:$V$17),0,SUM(N15,P15)) -> 2625000 | R15: =IF(L15>$Y$12,0,(IF(L15<=$V$17,0,$Y$14))) -> 0 | S15: =S14-N15 -> 525000000 | T15: =N15+P15 -> 2625000 | U15: 년이율 (%) | V15: 0.06
A16: 13년 | B16: =B15*0.995 -> 756123.11 | C16: =B16*$V$6 -> 1.1119547e+08 | D16: =B16*$V$8*$V$7 -> 89795669 | E16: =C16+D16 -> 2.0099113e+08 | F16: =(C16+D16)*0.03 -> 6029734 | G16: =C16+D16-F16 -> 1.949614e+08 | H16: =G16/12 -> 16246783 | I16: =I15+G16 -> 2.6123411e+09 | J16: =H16-(SUM($P$4:$P$15)/12) -> 13840533 | K16: =SUM($G$4:G16)-SUM($P$4:P159) -> 2.2914134e+09 | L16: 13 | M16: =EDATE($Y$13,L16) -> 44593 | N16: =IF(L16<=$V$17,0,(IF(L16<=$Y$12,R16-O16,0))) -> 0 | O16: =S15*$V$15/12 -> 2625000 | P16: =IF(S16>0,O16,IF(R16>0,O16,0)) -> 2625000 | Q16: =IF(L16>SUM($V$16:$V$17),0,SUM(N16,P16)) -> 2625000 | R16: =IF(L16>$Y$12,0,(IF(L16<=$V$17,0,$Y$14))) -> 0 | S16: =S15-N16 -> 525000000 | T16: =N16+P16 -> 2625000 | U16: 상환기간 | V16: 120 | X16: 대출액 | Y16: 1050000
A17: 14년 | B17: =B16*0.995 -> 752342.5 | C17: =B17*$V$6 -> 1.1063949e+08 | D17: =B17*$V$8*$V$7 -> 89346690 | E17: =C17+D17 -> 1.9998618e+08 | F17: =(C17+D17)*0.03 -> 5999585.3 | G17: =C17+D17-F17 -> 1.9398659e+08 | H17: =G17/12 -> 16165549 | I17: =I16+G17 -> 2.8063277e+09 | J17: =H17-(SUM($P$4:$P$15)/12) -> 13759299 | K17: =SUM($G$4:G17)-SUM($P$4:P171) -> 2.4792446e+09 | L17: 14 | M17: =EDATE($Y$13,L17) -> 44621 | N17: =IF(L17<=$V$17,0,(IF(L17<=$Y$12,R17-O17,0))) -> 0 | O17: =S16*$V$15/12 -> 2625000 | P17: =IF(S17>0,O17,IF(R17>0,O17,0)) -> 2625000 | Q17: =IF(L17>SUM($V$16:$V$17),0,SUM(N17,P17)) -> 2625000 | R17: =IF(L17>$Y$12,0,(IF(L17<=$V$17,0,$Y$14))) -> 0 | S17: =S16-N17 -> 525000000 | T17: =N17+P17 -> 2625000 | U17: 거치기간 | V17: 60
A18: 15년 | B18: =B17*0.995 -> 748580.79 | C18: =B18*$V$6 -> 1.1008629e+08 | D18: =B18*$V$8*$V$7 -> 88899957 | E18: =C18+D18 -> 1.9898625e+08 | F18: =(C18+D18)*0.03 -> 5969587.4 | G18: =C18+D18-F18 -> 1.9301666e+08 | H18: =G18/12 -> 16084722 | I18: =I17+G18 -> 2.9993444e+09 | J18: =H18-(SUM($P$4:$P$15)/12) -> 13678472 | K18: =SUM($G$4:G18)-SUM($P$4:P183) -> 2.6700402e+09 | L18: 15 | M18: =EDATE($Y$13,L18) -> 44652 | N18: =IF(L18<=$V$17,0,(IF(L18<=$Y$12,R18-O18,0))) -> 0 | O18: =S17*$V$15/12 -> 2625000 | P18: =IF(S18>0,O18,IF(R18>0,O18,0)) -> 2625000 | Q18: =IF(L18>SUM($V$16:$V$17),0,SUM(N18,P18)) -> 2625000 | R18: =IF(L18>$Y$12,0,(IF(L18<=$V$17,0,$Y$14))) -> 0 | S18: =S17-N18 -> 525000000 | T18: =N18+P18 -> 2625000 | U18: ♦ 태양광 최종수익 ♦
A19: 16년 | B19: =B18*0.995 -> 744837.88 | C19: =B19*$V$6 -> 1.0953586e+08 | D19: =B19*$V$8*$V$7 -> 88455457 | E19: =C19+D19 -> 1.9799132e+08 | F19: =(C19+D19)*0.03 -> 5939739.5 | G19: =C19+D19-F19 -> 1.9205158e+08 | H19: =G19/12 -> 16004298 | I19: =I18+G19 -> 3.1913959e+09 | J19: =H19-(SUM($P$4:$P$15)/12) -> 13598048 | K19: =SUM($G$4:G19)-SUM($P$4:P195) -> 2.8620918e+09 | L19: 16 | M19: =EDATE($Y$13,L19) -> 44682 | N19: =IF(L19<=$V$17,0,(IF(L19<=$Y$12,R19-O19,0))) -> 0 | O19: =S18*$V$15/12 -> 2625000 | P19: =IF(S19>0,O19,IF(R19>0,O19,0)) -> 2625000 | Q19: =IF(L19>SUM($V$16:$V$17),0,SUM(N19,P19)) -> 2625000 | R19: =IF(L19>$Y$12,0,(IF(L19<=$V$17,0,$Y$14))) -> 0 | S19: =S18-N19 -> 525000000 | T19: =N19+P19 -> 2625000 | U19: ROI (투자자본수익률) | V19: =I4/V12 -> 0.37645145
A20: 17년 | B20: =B19*0.995 -> 741113.69 | C20: =B20*$V$6 -> 1.0898818e+08 | D20: =B20*$V$8*$V$7 -> 88013180 | E20: =C20+D20 -> 1.9700136e+08 | F20: =(C20+D20)*0.03 -> 5910040.8 | G20: =C20+D20-F20 -> 1.9109132e+08 | H20: =G20/12 -> 15924277 | I20: =I19+G20 -> 3.3824872e+09 | J20: =H20-(SUM($P$4:$P$15)/12) -> 13518027 | K20: =SUM($G$4:G20)-SUM($P$4:P207) -> 3.0531831e+09 | L20: 17 | M20: =EDATE($Y$13,L20) -> 44713 | N20: =IF(L20<=$V$17,0,(IF(L20<=$Y$12,R20-O20,0))) -> 0 | O20: =S19*$V$15/12 -> 2625000 | P20: =IF(S20>0,O20,IF(R20>0,O20,0)) -> 2625000 | Q20: =IF(L20>SUM($V$16:$V$17),0,SUM(N20,P20)) -> 2625000 | R20: =IF(L20>$Y$12,0,(IF(L20<=$V$17,0,$Y$14))) -> 0 | S20: =S19-N20 -> 525000000 | T20: =N20+P20 -> 2625000 | U20: 손익분기점 (년) | V20: =V12/I4 -> 2.656385
A21: 18년 | B21: =B20*0.995 -> 737408.12 | C21: =B21*$V$6 -> 1.0844324e+08 | D21: =B21*$V$8*$V$7 -> 87573114 | E21: =C21+D21 -> 1.9601635e+08 | F21: =(C21+D21)*0.03 -> 5880490.6 | G21: =C21+D21-F21 -> 1.9013586e+08 | H21: =G21/12 -> 15844655 | I21: =I20+G21 -> 3.5726231e+09 | J21: =H21-(SUM($P$4:$P$15)/12) -> 13438405 | K21: =SUM($G$4:G21)-SUM($P$4:P219) -> 3.2433189e+09 | L21: 18 | M21: =EDATE($Y$13,L21) -> 44743 | N21: =IF(L21<=$V$17,0,(IF(L21<=$Y$12,R21-O21,0))) -> 0 | O21: =S20*$V$15/12 -> 2625000 | P21: =IF(S21>0,O21,IF(R21>0,O21,0)) -> 2625000 | Q21: =IF(L21>SUM($V$16:$V$17),0,SUM(N21,P21)) -> 2625000 | R21: =IF(L21>$Y$12,0,(IF(L21<=$V$17,0,$Y$14))) -> 0 | S21: =S20-N21 -> 525000000 | T21: =N21+P21 -> 2625000 | U21: 20년 총수익 (無대출) | V21: =I23 -> 3.9500475e+09
A22: 19년 | B22: =B21*0.995 -> 733721.08 | C22: =B22*$V$6 -> 1.0790102e+08 | D22: =B22*$V$8*$V$7 -> 87135248 | E22: =C22+D22 -> 1.9503627e+08 | F22: =(C22+D22)*0.03 -> 5851088.1 | G22: =C22+D22-F22 -> 1.8918518e+08 | H22: =G22/12 -> 15765432 | I22: =I21+G22 -> 3.7618083e+09 | J22: =H22-(SUM($P$4:$P$15)/12) -> 13359182 | K22: =SUM($G$4:G22)-SUM($P$4:P231) -> 3.4325041e+09 | L22: 19 | M22: =EDATE($Y$13,L22) -> 44774 | N22: =IF(L22<=$V$17,0,(IF(L22<=$Y$12,R22-O22,0))) -> 0 | O22: =S21*$V$15/12 -> 2625000 | P22: =IF(S22>0,O22,IF(R22>0,O22,0)) -> 2625000 | Q22: =IF(L22>SUM($V$16:$V$17),0,SUM(N22,P22)) -> 2625000 | R22: =IF(L22>$Y$12,0,(IF(L22<=$V$17,0,$Y$14))) -> 0 | S22: =S21-N22 -> 525000000 | T22: =N22+P22 -> 2625000 | U22: 20년 총수익 (대출적용) | V22: =K23 -> 3.6207434e+09
A23: 20년 | B23: =B22*0.995 -> 730052.48 | C23: =B23*$V$6 -> 1.0736152e+08 | D23: =B23*$V$8*$V$7 -> 86699572 | E23: =C23+D23 -> 1.9406109e+08 | F23: =(C23+D23)*0.03 -> 5821832.7 | G23: =C23+D23-F23 -> 1.8823926e+08 | H23: =G23/12 -> 15686605 | I23: =I22+G23 -> 3.9500475e+09 | J23: =H23-(SUM($P$4:$P$15)/12) -> 13280355 | K23: =SUM($G$4:G23)-SUM($P$4:P243) -> 3.6207434e+09 | L23: 20 | M23: =EDATE($Y$13,L23) -> 44805 | N23: =IF(L23<=$V$17,0,(IF(L23<=$Y$12,R23-O23,0))) -> 0 | O23: =S22*$V$15/12 -> 2625000 | P23: =IF(S23>0,O23,IF(R23>0,O23,0)) -> 2625000 | Q23: =IF(L23>SUM($V$16:$V$17),0,SUM(N23,P23)) -> 2625000 | R23: =IF(L23>$Y$12,0,(IF(L23<=$V$17,0,$Y$14))) -> 0 | S23: =S22-N23 -> 525000000 | T23: =N23+P23 -> 2625000
A24: # 이 수지분석은 2024년 현물시장 기준 수익분석 자료입니다. # 선로 개통비 , 구조 보강비 별도 / 순 공사비 기준 수익분석 자료 입니다. | L24: 21 | M24: =EDATE($Y$13,L24) -> 44835 | N24: =IF(L24<=$V$17,0,(IF(L24<=$Y$12,R24-O24,0))) -> 0 | O24: =S23*$V$15/12 -> 2625000 | P24: =IF(S24>0,O24,IF(R24>0,O24,0)) -> 2625000 | Q24: =IF(L24>SUM($V$16:$V$17),0,SUM(N24,P24)) -> 2625000 | R24: =IF(L24>$Y$12,0,(IF(L24<=$V$17,0,$Y$14))) -> 0 | S24: =S23-N24 -> 525000000 | T24: =N24+P24 -> 2625000
L25: 22 | M25: =EDATE($Y$13,L25) -> 44866 | N25: =IF(L25<=$V$17,0,(IF(L25<=$Y$12,R25-O25,0))) -> 0 | O25: =S24*$V$15/12 -> 2625000 | P25: =IF(S25>0,O25,IF(R25>0,O25,0)) -> 2625000 | Q25: =IF(L25>SUM($V$16:$V$17),0,SUM(N25,P25)) -> 2625000 | R25: =IF(L25>$Y$12,0,(IF(L25<=$V$17,0,$Y$14))) -> 0 | S25: =S24-N25 -> 525000000 | T25: =N25+P25 -> 2625000
L26: 23 | M26: =EDATE($Y$13,L26) -> 44896 | N26: =IF(L26<=$V$17,0,(IF(L26<=$Y$12,R26-O26,0))) -> 0 | O26: =S25*$V$15/12 -> 2625000 | P26: =IF(S26>0,O26,IF(R26>0,O26,0)) -> 2625000 | Q26: =IF(L26>SUM($V$16:$V$17),0,SUM(N26,P26)) -> 2625000 | R26: =IF(L26>$Y$12,0,(IF(L26<=$V$17,0,$Y$14))) -> 0 | S26: =S25-N26 -> 525000000 | T26: =N26+P26 -> 2625000
L27: 24 | M27: =EDATE($Y$13,L27) -> 44927 | N27: =IF(L27<=$V$17,0,(IF(L27<=$Y$12,R27-O27,0))) -> 0 | O27: =S26*$V$15/12 -> 2625000 | P27: =IF(S27>0,O27,IF(R27>0,O27,0)) -> 2625000 | Q27: =IF(L27>SUM($V$16:$V$17),0,SUM(N27,P27)) -> 2625000 | R27: =IF(L27>$Y$12,0,(IF(L27<=$V$17,0,$Y$14))) -> 0 | S27: =S26-N27 -> 525000000 | T27: =N27+P27 -> 2625000
L28: 25 | M28: =EDATE($Y$13,L28) -> 44958 | N28: =IF(L28<=$V$17,0,(IF(L28<=$Y$12,R28-O28,0))) -> 0 | O28: =S27*$V$15/12 -> 2625000 | P28: =IF(S28>0,O28,IF(R28>0,O28,0)) -> 2625000 | Q28: =IF(L28>SUM($V$16:$V$17),0,SUM(N28,P28)) -> 2625000 | R28: =IF(L28>$Y$12,0,(IF(L28<=$V$17,0,$Y$14))) -> 0 | S28: =S27-N28 -> 525000000 | T28: =N28+P28 -> 2625000
L29: 26 | M29: =EDATE($Y$13,L29) -> 44986 | N29: =IF(L29<=$V$17,0,(IF(L29<=$Y$12,R29-O29,0))) -> 0 | O29: =S28*$V$15/12 -> 2625000 | P29: =IF(S29>0,O29,IF(R29>0,O29,0)) -> 2625000 | Q29: =IF(L29>SUM($V$16:$V$17),0,SUM(N29,P29)) -> 2625000 | R29: =IF(L29>$Y$12,0,(IF(L29<=$V$17,0,$Y$14))) -> 0 | S29: =S28-N29 -> 525000000 | T29: =N29+P29 -> 2625000
L30: 27 | M30: =EDATE($Y$13,L30) -> 45017 | N30: =IF(L30<=$V$17,0,(IF(L30<=$Y$12,R30-O30,0))) -> 0 | O30: =S29*$V$15/12 -> 2625000 | P30: =IF(S30>0,O30,IF(R30>0,O30,0)) -> 2625000 | Q30: =IF(L30>SUM($V$16:$V$17),0,SUM(N30,P30)) -> 2625000 | R30: =IF(L30>$Y$12,0,(IF(L30<=$V$17,0,$Y$14))) -> 0 | S30: =S29-N30 -> 525000000 | T30: =N30+P30 -> 2625000
L31: 28 | M31: =EDATE($Y$13,L31) -> 45047 | N31: =IF(L31<=$V$17,0,(IF(L31<=$Y$12,R31-O31,0))) -> 0 | O31: =S30*$V$15/12 -> 2625000 | P31: =IF(S31>0,O31,IF(R31>0,O31,0)) -> 2625000 | Q31: =IF(L31>SUM($V$16:$V$17),0,SUM(N31,P31)) -> 2625000 | R31: =IF(L31>$Y$12,0,(IF(L31<=$V$17,0,$Y$14))) -> 0 | S31: =S30-N31 -> 525000000 | T31: =N31+P31 -> 2625000
L32: 29 | M32: =EDATE($Y$13,L32) -> 45078 | N32: =IF(L32<=$V$17,0,(IF(L32<=$Y$12,R32-O32,0))) -> 0 | O32: =S31*$V$15/12 -> 2625000 | P32: =IF(S32>0,O32,IF(R32>0,O32,0)) -> 2625000 | Q32: =IF(L32>SUM($V$16:$V$17),0,SUM(N32,P32)) -> 2625000 | R32: =IF(L32>$Y$12,0,(IF(L32<=$V$17,0,$Y$14))) -> 0 | S32: =S31-N32 -> 525000000 | T32: =N32+P32 -> 2625000
L33: 30 | M33: =EDATE($Y$13,L33) -> 45108 | N33: =IF(L33<=$V$17,0,(IF(L33<=$Y$12,R33-O33,0))) -> 0 | O33: =S32*$V$15/12 -> 2625000 | P33: =IF(S33>0,O33,IF(R33>0,O33,0)) -> 2625000 | Q33: =IF(L33>SUM($V$16:$V$17),0,SUM(N33,P33)) -> 2625000 | R33: =IF(L33>$Y$12,0,(IF(L33<=$V$17,0,$Y$14))) -> 0 | S33: =S32-N33 -> 525000000 | T33: =N33+P33 -> 2625000
L34: 31 | M34: =EDATE($Y$13,L34) -> 45139 | N34: =IF(L34<=$V$17,0,(IF(L34<=$Y$12,R34-O34,0))) -> 0 | O34: =S33*$V$15/12 -> 2625000 | P34: =IF(S34>0,O34,IF(R34>0,O34,0)) -> 2625000 | Q34: =IF(L34>SUM($V$16:$V$17),0,SUM(N34,P34)) -> 2625000 | R34: =IF(L34>$Y$12,0,(IF(L34<=$V$17,0,$Y$14))) -> 0 | S34: =S33-N34 -> 525000000 | T34: =N34+P34 -> 2625000
L35: 32 | M35: =EDATE($Y$13,L35) -> 45170 | N35: =IF(L35<=$V$17,0,(IF(L35<=$Y$12,R35-O35,0))) -> 0 | O35: =S34*$V$15/12 -> 2625000 | P35: =IF(S35>0,O35,IF(R35>0,O35,0)) -> 2625000 | Q35: =IF(L35>SUM($V$16:$V$17),0,SUM(N35,P35)) -> 2625000 | R35: =IF(L35>$Y$12,0,(IF(L35<=$V$17,0,$Y$14))) -> 0 | S35: =S34-N35 -> 525000000 | T35: =N35+P35 -> 2625000
L36: 33 | M36: =EDATE($Y$13,L36) -> 45200 | N36: =IF(L36<=$V$17,0,(IF(L36<=$Y$12,R36-O36,0))) -> 0 | O36: =S35*$V$15/12 -> 2625000 | P36: =IF(S36>0,O36,IF(R36>0,O36,0)) -> 2625000 | Q36: =IF(L36>SUM($V$16:$V$17),0,SUM(N36,P36)) -> 2625000 | R36: =IF(L36>$Y$12,0,(IF(L36<=$V$17,0,$Y$14))) -> 0 | S36: =S35-N36 -> 525000000 | T36: =N36+P36 -> 2625000
... L243: 240 | M243: =EDATE($Y$13,L243) -> 51502 | N243: =IF(L243<=$V$17,0,(IF(L243<=$Y$12,R243-O243,0))) -> 0 | O243: =S242*$V$15/12 -> 2.4400651e-09 | P243: =IF(S243>0,O243,IF(R243>0,O243,0)) -> 2.4400651e-09 | Q243: =IF(L243>SUM($V$16:$V$17),0,SUM(N243,P243)) -> 0 | R243: =IF(L243>$Y$12,0,(IF(L243<=$V$17,0,$Y$14))) -> 0 | S243: =S242-N243 -> 4.8801303e-07 | T243: =N243+P243 -> 2.4400651e-09

Sheet 견적서 작업용
A1: 견 적 서
A3: 강동농협 사업주 | C3: 귀하 | E3: │주│솔 라 엘 디 (인)
A5: 현 장 명 : 경상북도 경주시 강동면 인동리75번지, 단구리 1259 | F5: ◈주 소: 대구광역시 동구 메디밸리로19 401호
F6: 전 화 : (0 5 3) 8 5 6 - 9 6 9 8
A7: 공 사 명 : 태양광설치 공사 | F7: F A X : (0 5 3) 2 8 9 - 6 6 9 8
A9: 하기와 같이 견적합니다. | G9: 견적송부일 : | H9: =TODAY() -> 46133
H14: (금액단위:원)
A15: 기호 | B15: 품 명 | C15: 규 격 | D15: 단 위 | E15: 수 량 | F15: 단 가 | G15: 금 액 | H15: 비 고 | J15: 삭제금지
A16: 1 | B16: 한화 620W 무등급모듈 | G16: 141399400 | J16: =현물가1.5!$Z$4 -> 152 | K16: 1000 | L16: =PRODUCT(J16:K16) -> 152000 | M16: 600 | N16: =L16/M16 -> 253.33333 | O16: =ROUND(N16,-1) -> 250 | P16: =ROUNDUP(O16,-1) -> 250
A17: 2 | B17: 현대 60kw | G17: 30000000 | J17: =현물가1.5!$Z$4 -> 152 | K17: 50 | L17: =J17/K17 -> 3.04 | M17: =ROUNDUP(L17,0) -> 4
A18: 3 | B18: 시설공사 및 대관비용 | G18: =SUM(G19)-(G16+G17) -> 164964236
B19: 태양광 발전소 공사 | G19: 336363636
A20: * 견적조건 | J20: 한화 | K20: 한화 600W 무등급 양면모듈
B21: 1. VAT별도 | J21: 진코 | K21: 진코 620W 무등급 양면모듈
B22: 2. 모듈 : 제조사 보증서 제출
B23: 3. 인버터 : 제조사 보증서 제출 | J23: =현물가1.5!Z1 -> 진코 | K23: =IF(J23=J21,K21,K20) -> 진코 620W 무등급 양면모듈
B24: 4. 한전연계비용 별도 (표준시설부담금)
B25: 5. 안전관리자 선임 별도
B26: 6. 보강 발생 시 비용 별도 ( 실비처리 )

Sheet 123213123
A1: 태양광 발전소 시설공사 세부견적서
A2: ( 금액단위 : 원 )
A3: 구분 | B3: 항목 | D3: 용량 | E3: 수량 | F3: 단가 | G3: 합계 | H3: 비고
A4: 시설공사 | B4: 원자재 | C4: 모듈 ( 한화 620W N타입 ) | D4: 327.36kw | E4: 528 | F4: 271000 | G4: =SUM(E4*F4) -> 143088000 | H4: 무등급
C5: 인버터 ( 현대 60kw ) | E5: 6 | F5: 5000000 | G5: =SUM(E5*F5) -> 30000000
C6: 구조물가공 및 제작 | E6: 328 | F6: 140000 | G6: =SUM(E6*F6) -> 45920000 | H6: 포스맥
C7: 볼트류외 부자재 | E7: 328 | F7: 45000 | G7: =SUM(E7*F7) -> 14760000
C8: 분전반 | E8: 6 | F8: 1000000 | G8: =SUM(E8*F8) -> 6000000
G9: =SUM(E9*F9) -> 0
B10: 현장 설치 | C10: 구조물설치 ( 모듈설치 및 장비포함 ) | D10: 327.36kw | E10: 328 | F10: 100000 | G10: =SUM(E10*F10) -> 32800000
B12: 전기 공사 | C12: 전기자재구입 ( 난연케이블 및 Tray 외 기타전기자재 ) | D12: 327.36kw | E12: 328 | F12: 135000 | G12: =SUM(E12*F12) -> 44280000
C13: 전기공사
B14: 부대 비용 | C14: 구조설계 및 사용전검사 ( 전기안전공사 ) | D14: 327.36kw | G14: 3000000
C15: 전기설계 및 감리 | G15: 4000000
G16: =SUM(E16*F16) -> 0
B17: 시설 공사 소계 | G17: =SUM(G4:G16) -> 323848000
A18: 일반 | B18: 일반 | C18: 일반 관리비 ( 회사이윤 및 경비) | F18: 0.07 | G18: 24800000
C19: 모듈변경에 따른 할인금액 (100kw당 10,000,000원) | G19: -30000000
C20: 단위절삭 | G20: -512800
B21: 소계 | G21: =SUM(G18+G19) -> -5200000
B25: 소계 | G25: =SUM(G22:G24) -> 0
A26: 합계 | D26: =SUM(G17,G21,G25) -> 318648000 | L26: 336363640
A27: VAT | D27: =SUM(D26*0.1) -> 31864800 | L27: =SUM(L26*0.1) -> 33636364
A28: 합계 (Vat포함) | D28: =SUM(D26:H27)+G20 -> 350000000 | L28: =SUM(L26:L27) -> 370000004
A29: 특이사항
A30: 1. VAT별도
A31: 2. 모듈 : 제조사 보증서 제출
A32: 3. 인버터 : 제조사 보증서 제출
A33: 4. 한전연계비용 별도, 전기안전관리 및 보안경비 별도
A34: 5. 약 307kw기준 (kw당1,095,647원) > 327kw기준 (kw당 974,458원)
A35: 6

Sheet Sheet3
A1: 견 적 서
A3: 업 체 명 | E3: 강동농협 입찰 | U3: 업 체 명 | Y3: ㈜솔라엘디
A4: 견적일자 | E4: 2024.01.24
A5: 유효기간 | E5: 1개월 | U5: MAIL주소 | Y5: slddettkh@naver.com
K6: 아래와 같이 견적합니다.
A7: 내 용 | E7: 설치용량 | I7: 307.39kw | U7: 설지형태 | Y7: 공장 지붕형(고정형)
A8: 금 액 | E8: 견적금액 | I8: 삼억칠천만원 정 | U8: 원정 | Y8: 370000000 | AG8: VAT포함
A10: 구분 | C10: 품목 | E10: 규 격 | H10: 내 용 | P10: 단위 | R10: 수 량 | U10: 단 가 | Y10: 금 액 | AD10: 비 고
A11: 자 재 | C11: 모듈 | E11: 모델명 | H11: 현대모듈:590wp | P11: EA | R11: 521 | U11: 271400 | Y11: =+R11*U11 -> 141399400 | AD11: 모듈:550wp
E12: 제조사 | H12: 현대에너지 솔루션
E13: CELL종류 | H13: 156셀
E14: 정격출력 | H14: 590kw
E15: 제품보증
E16: 출력보증
E17: 출력보증
C18: 인버터 | E18: 모델명 | H18: 현대 60kw | P18: EA | R18: 6 | U18: 5000000 | Y18: =R18*U18 -> 30000000 | AD18: 스트링/접속반내장형/
E19: 유로효율
E20: 제조사 | H20: 현대에너지 솔루션
E21: 정격출력 | H21: 60Kw
E22: 상수
E23: 토플로지
C24: 구조물 | E24: 설비형태 | H24: 슬라브/경사형지붕 | P24: kw | R24: 307 | U24: 180000 | Y24: =R24*U24 -> 55260000 | AD24: 포스멕/용융/알루미늄
E25: 구조물 | H25: 포스멕/용융/알루미늄
E26: 규격
C27: 접속반 | R27: 2 | U27: 3500000 | Y27: =R27*U27 -> 7000000
C28: 분전함 | P28: EA | R28: 6 | U28: 1500000 | Y28: =U28*R28 -> 9000000
C29: 수배전반 | P29: EA | R29: 0
C30: 전기자재 | P30: EA | R30: 1 | U30: 1170000 | Y30: 1170000
C31: 모니터링 | P31: EA | R31: 2 | U31: 1000000 | Y31: =U31*R31 -> 2000000 | AD31: 인버터 내장형
C32: CCTV | Y32: =R32*U32 -> 0
C33: 휀스
A34: 소 계 | Y34: =SUM(Y11:AC33) -> 245829400
A35: 노무비 | C35: 모듈설치 | H35: 노 무 비 | P35: KW | R35: 318 | U35: 50000 | Y35: =U35*R35 -> 15900000
C36: 구조물설치 | H36: 노 무 비 | P36: KW | R36: 318 | U36: 120000 | Y36: =R36*U36 -> 38160000
C37: 전기공사 | H37: 노 무 비 | P37: KW | R37: 318 | U37: 100000 | Y37: =U37*R37 -> 31800000
C38: 휀스 | H38: 노 무 비 | U38: 0
C39: 간접노무비 | H39: 노 무 비 | P39: 0
A40: 소 계 | Y40: =SUM(Y35:AC39) -> 85860000
A41: 토목 공사 | C41: 기초토목
C42: 기업이윤 | Y42: 25900000
...
